Workbook

Sheet Léame
B2: Modelo de datos · TRIM Hidrocarburos
B3: Las tablas que guarda el backend y cómo se relacionan (PostgreSQL 16)
B5: CÓMO SE LEE
B6: Tablas | C6: Una fila por tabla: su grupo, para qué sirve, el tipo TypeScript del front que guarda, quién la escribe, qué endpoint la lee y sus reglas. «Columnas» y «Relaciones que salen» se cuentan con fórmulas sobre las otras hojas.
B7: Columnas | C7: Una fila por columna: tipo PostgreSQL, si admite nulo, clave primaria (PK), clave foránea (FK: tabla.columna a la que apunta), único, restricción CHECK, descripción y un valor de ejemplo del demo. Use el filtro de la cabecera para ver una tabla.
B8: Relaciones | C8: Cada clave foránea dicha en palabras: de qué columna a qué columna, su cardinalidad (N:1 = muchas filas de la primera apuntan a una de la segunda) y qué significa.
B9: Filas de ejemplo | C9: Filas reales del demo (ids, fechas y valores de referencia/insumos), tabla por tabla. No son datos de un cliente.
B10: Diagrama | C10: El diagrama entidad-relación de cada grupo, el mismo del capítulo 3 del documento.
B11: Fuente de verdad | C11: El archivo que se ejecuta es esquema.sql (docs/backend/). Este libro se genera desde la misma especificación y se comprobó que coincide tabla por tabla y columna por columna.
B13: GRUPOS
B14: Registro de campos y planta | C14: Quién es cada campo, qué activos tiene (equipos de superficie y pozos) y la topología de su planta. Un cliente nuevo son filas aquí, no código.
B15: Cadena de datos | C15: Del gateway del borde al tag: se llena sola con el nacimiento de Sparkplug B (NBIRTH/DBIRTH). Da la procedencia de cada número y la banda normal versionada de cada tag.
B16: Series | C16: La lectura de cada tag en el tiempo (tag, instante, valor, calidad), particionada por mes; opcionalmente hipertabla de TimescaleDB.
B17: Insumos del motor | C17: Lo que el borde entrega y el motor consume (interfaz Insumos): pozos y pruebas, eventos de los controladores, paradas de bombas, caídas de servicios, fiscal diario, metrología, perfiles de bomba, límites y alarmas, y el catálogo de daños de ISO 14224.
B18: Configuración firmada | C18: Lo único técnico que entra a mano: metas, precio, regla de cierre, perfil, tanques, respaldos, programa y membrete. Cada firma es una versión completa e inmutable.
B19: Personas | C19: Roles y capacidades del producto, usuarios con sus campos y su WhatsApp, la identidad del SSO y el rastro de cambios de acceso.
B20: Lo que entra a mano y WhatsApp | C20: Respuestas de los operarios, análisis de confiabilidad, informes con folio, el registro de WhatsApp (saliente y entrante), predicciones del vigía, la asignación oficial cargada y los cambios de planta.
B21: Lo que se lee de SAP PM | C21: Espejo de lo que TRIM necesita de SAP: identidad del equipo, avisos, órdenes con sus horas y repuestos, y stock. TRIM no crea órdenes.
B22: Precálculo de meses cerrados | C22: Caché verificable del motor para meses cerrados y publicados: libro del mes por campo, factor de asignación, tramos por día y asignación por pozo.
B24: TOTALES
B25: Tablas | C25: =COUNTA(Tablas!B:B)-1
B26: Columnas | C26: =COUNTA(Columnas!B:B)-1
B27: Relaciones | C27: =COUNTA(Relaciones!A:A)-1

Sheet Tablas
A1: Grupo | B1: Tabla | C1: Para qué sirve | D1: Tipo TS (front) | E1: Quién la escribe | F1: Endpoints que la leen o escriben | G1: Reglas | H1: Columnas | I1: Relaciones que salen
A2: Registro de campos y planta | B2: campo | C2: Registro de campos de la empresa (tipo Campo, src/entities/tipos.ts). GET /api/campos. Un cliente nuevo son filas aquí, no código. Las metas, el perfil y el precio NO viven aquí: son configuración firmada. | D2: Campo (src/entities/tipos.ts) | E2: Implementación (alta de un cliente o de un campo); no hay endpoint de escritura. | F2: GET /api/campos | G2: El catálogo no puede traer un campo que no esté aquí (el arranque se detiene). La configuración firmada solo acepta campos del registro (validarConfig, 422). | H2: =COUNTIF(Columnas!$B:$B,B2) | I2: =COUNTIF(Relaciones!$A:$A,B2)
A3: Registro de campos y planta | B3: activo | C3: Supertipo: todo lo que tiene código en un campo. clase=catalogo es un equipo de superficie (tabla equipo); clase=pozo es un pozo (tabla pozo). Corresponde a ClaseEquipo de src/entities/equipo-vivo.ts. Un mismo código existe en varios campos (P-201B): la identidad es (campo, código). | D3: ClaseEquipo (src/entities/equipo-vivo.ts) | E3: Servidor, al dar de alta un equipo o un pozo. | F3: (interna: destino de las FK a «equipo o pozo») | G3: Un código es único en su campo; el mismo código existe en varios campos (P-201B). Único: (campo_id, codigo, clase). | H3: =COUNTIF(Columnas!$B:$B,B3) | I3: =COUNTIF(Relaciones!$A:$A,B3)
A4: Registro de campos y planta | B4: equipo | C4: Registro de ingeniería: un equipo de superficie en un campo (la parte estática de Equipo/EquipoEnCampo, src/entities/tipos.ts y equipos.ts). Lo declara el cliente una vez. Sale en GET /api/catalogo → campos[c].registroEquipos y en el inventario de Conectores. Lo vivo (marcha, estado, severidad, lecturas) NO se guarda aquí: lo calcula el servidor. | D4: Equipo / EquipoEnCampo, parte estática (src/entities/tipos.ts, equipos.ts) | E4: Ingeniería del cliente, una vez por campo (registro de ingeniería). | F4: GET /api/catalogo → campos[c].registroEquipos GET /api/campos/:campo/inventario → equipos GET /api/vistas/equipos… | G4: servicio dice qué tipo de causa se carga cuando cae (aire, energia…); la regla no depende del id. equipo.fiscal de la API sale de punto_medicion. aguas_abajo y redundancia son del registro del campo; en una bomba de la línea van NULL y la API los arma del respaldo firmado (respaldoEnCampo). | H4: =COUNTIF(Columnas!$B:$B,B4) | I4: =COUNTIF(Relaciones!$A:$A,B4)
A5: Registro de campos y planta | B5: planta_campo | C5: Cabecera del esquema de planta de un campo: caudales de diseño y los cuatro cuellos de botella (Caudales y Chokes de PlantaCampo, src/entities/planta.ts). Sale en GET /api/catalogo → campos[c].planta. Un campo sin fila aquí no trae planta (hueco), nunca la de otro. | D5: PlantaCampo: caudales, chokes, nota (src/entities/planta.ts) | E5: Implementación; los cambios de trenes y miembros por POST /api/planta/cambios (conector:configurar). | F5: GET /api/catalogo → campos[c].planta | G5: Un campo sin planta no trae planta (hueco), nunca la de otro. | H5: =COUNTIF(Columnas!$B:$B,B5) | I5: =COUNTIF(Relaciones!$A:$A,B5)
A6: Registro de campos y planta | B6: planta_elemento | C6: Un elemento de un tren del esquema de planta (Elemento, src/entities/planta.ts). Cambia solo con POST /api/planta/cambios (agregar-elemento, quitar-elemento), que registra cambio_planta. | D6: Elemento (src/entities/planta.ts) | E6: Servidor al aplicar aplicarCambioPlanta (administrador, conector:configurar). | F6: GET /api/catalogo → campos[c].planta POST /api/planta/cambios (agregar-elemento, quitar-elemento) | G6: Un id no se repite entre elementos y miembros del campo (409/422). Único: (campo_id, tren, orden). Un id no se repite entre elementos y miembros del campo. [trigger planta_elemento_id_unico: INSERT UPDATE] | H6: =COUNTIF(Columnas!$B:$B,B6) | I6: =COUNTIF(Relaciones!$A:$A,B6)
A7: Registro de campos y planta | B7: planta_miembro | C7: Miembro de un elemento con varios del mismo tipo (pozos, tanques en especificación): Miembro de src/entities/planta.ts. Cambia con agregar-miembro / quitar-miembro. | D7: Miembro (src/entities/planta.ts) | E7: Servidor al aplicar aplicarCambioPlanta. | F7: GET /api/catalogo → campos[c].planta POST /api/planta/cambios (agregar-miembro, quitar-miembro) | G7: El grupo tiene que existir y admitir miembros (422 «Ese conjunto no existe»). Único: (campo_id, elemento_id, orden). Un id no se repite entre elementos y miembros del campo. [trigger planta_miembro_id_unico: INSERT UPDATE] | H7: =COUNTIF(Columnas!$B:$B,B7) | I7: =COUNTIF(Relaciones!$A:$A,B7)
A8: Cadena de datos | B8: gateway | C8: Gateway del borde (nodo de Sparkplug B): se crea solo al recibir su NBIRTH. Es del campo donde se inscribió; si se presenta con otro, el nacimiento se rechaza (403 gateway-de-otro-campo, tabla rechazo). GET /api/campos/:campo/inventario y bloque tecnico de la procedencia. | E8: Borde (NBIRTH), autenticado por certificado de cliente. | F8: POST /api/ingesta/nacimiento GET /api/campos/:campo/inventario GET …/tags/:tag/procedencia → tecnico | G8: Un gateway inscrito en un campo que se presenta con otro: 403 gateway-de-otro-campo y fila en rechazo. Único: (id, campo_id). | H8: =COUNTIF(Columnas!$B:$B,B8) | I8: =COUNTIF(Relaciones!$A:$A,B8)
A9: Cadena de datos | B9: inscripcion | C9: Código de un solo uso con que un gateway nuevo se inscribe en un campo (POST /api/inscripcion, capacidad conector:configurar). En producción se canjea por el certificado de cliente en el primer contacto. Se guarda la huella del código, nunca el código. | E9: Persona con conector:configurar y el campo asignado; el borde la canjea. | F9: POST /api/inscripcion | G9: Un solo uso; vence a las 24 h. Se guarda la huella del código, nunca el código. Único: (codigo_huella). | H9: =COUNTIF(Columnas!$B:$B,B9) | I9: =COUNTIF(Relaciones!$A:$A,B9)
A10: Cadena de datos | B10: nacimiento | C10: Bitácora de nacimientos aceptados (NBIRTH + DBIRTH; POST /api/ingesta/nacimiento → { gateway, tags, pendientes }). Solo inserción: cada reconexión de Sparkplug es una fila. | E10: Borde. | F10: POST /api/ingesta/nacimiento | G10: Todo o nada: con una falta, 400 con faltas[] y nada escrito. Solo inserción. Solo inserción: UPDATE, DELETE y TRUNCATE rechazados (SQLSTATE 23001). [trigger nacimiento_sin_truncate: TRUNCATE] Solo inserción: UPDATE, DELETE y TRUNCATE rechazados (SQLSTATE 23001). [trigger nacimiento_solo_insercion: UPDATE DELETE] | H10: =COUNTIF(Columnas!$B:$B,B10) | I10: =COUNTIF(Relaciones!$A:$A,B10)
A11: Cadena de datos | B11: rechazo | C11: Nacimientos rechazados: un borde que se presenta con otro campo o declara tags de otro gateway es un hecho de seguridad y queda escrito (fuera de la transacción del nacimiento, que se deshizo). Solo inserción. Sin FK: el gateway o el campo pueden no existir. | E11: Servidor, fuera de la transacción del nacimiento rechazado. | F11: POST /api/ingesta/nacimiento (403/409) | G11: Solo inserción. Solo inserción: UPDATE, DELETE y TRUNCATE rechazados (SQLSTATE 23001). [trigger rechazo_sin_truncate: TRUNCATE] Solo inserción: UPDATE, DELETE y TRUNCATE rechazados (SQLSTATE 23001). [trigger rechazo_solo_insercion: UPDATE DELETE] | H11: =COUNTIF(Columnas!$B:$B,B11) | I11: =COUNTIF(Relaciones!$A:$A,B11)
A12: Cadena de datos | B12: fuente | C12: Conector del borde hacia una fuente de datos del campo (un historiador PI, un servidor OPC UA, un PLC por Modbus, el computador de flujo por ROC Plus…). Sale de dispositivos[].fuente del nacimiento. El simulador junta fuente y dispositivo en una sola fila (id gateway:protocolo:dispositivo); aquí se separan. | E12: Borde (dispositivos[].fuente del DBIRTH). | F12: GET …/tags/:tag/procedencia → lectura.protocolo, tecnico.endpoint | G12: Siempre solo-lectura: TRIM no escribe en el PLC. Único: (gateway_id, protocolo, endpoint). Único: (id, gateway_id, campo_id). | H12: =COUNTIF(Columnas!$B:$B,B12) | I12: =COUNTIF(Relaciones!$A:$A,B12)
A13: Cadena de datos | B13: dispositivo | C13: Dispositivo de Sparkplug B declarado en un DBIRTH (dispositivos[] del nacimiento). Su nombre resuelve el mapeo: si coincide con el código de un equipo del campo, sus tags nacen descubiertos; si no, pendientes. | E13: Borde (DBIRTH). | F13: GET …/tags/:tag/procedencia → lectura.reloj | G13: Si el nombre coincide con un equipo del campo, sus tags nacen descubiertos; si no, pendientes. Único: (fuente_id, nombre). Único: (id, campo_id). Único: (id, gateway_id). | H13: =COUNTIF(Columnas!$B:$B,B13) | I13: =COUNTIF(Relaciones!$A:$A,B13)
A14: Cadena de datos | B14: tag | C14: Registro de tags (descubierto del DBIRTH). Un tag es único en su campo y es del campo de su gateway (FK compuesta tag→dispositivo→fuente→gateway). La banda normal declarada aquí es la ÚNICA fuente de LimiteTag.normal; si un re-nacimiento la cambia, lo anterior queda en historial_tag. GET …/procedencia, …/inventario, …/tags/pendientes, POST …/tags/:tag/equipo. | D14: LimiteTag.texto/normal (src/entities/limites.ts); procedencia.instrumento | E14: Borde (DBIRTH); el equipo, una persona con conector:configurar cuando el borde no lo resuelve. | F14: GET …/tags/:tag/procedencia GET /api/campos/:campo/inventario GET /api/campos/:campo/tags/pendientes POST /api/campos/:campo/tags/:tag/equipo GET /api/catalogo → limites | G14: Solo el gateway que lo publica lo vuelve a declarar (409 tag-de-otro-gateway). Un nacimiento nunca deshace un mapeo manual o por regla. Si un re-nacimiento cambia banda, unidad, cadencia o calibración, lo anterior va a historial_tag. Único: (campo_id, nombre). Solo su gateway lo vuelve a declarar; un nacimiento no deshace un mapeo manual o por regla. [trigger tag_reglas: UPDATE] | H14: =COUNTIF(Columnas!$B:$B,B14) | I14: =COUNTIF(Relaciones!$A:$A,B14)
A15: Cadena de datos | B15: historial_tag | C15: Versiones anteriores de la descripción de un tag: lo que un re-nacimiento cambió (banda normal, unidad, cadencia, clase o calibración) no se pierde. La banda que regía en un instante t es la de la primera fila con reemplazado > t, o la del tag si no la hay. Solo inserción. | E15: Servidor, en el nacimiento que cambia el tag. | F15: (auditoría; la banda que regía en t) | G15: Solo inserción. Solo inserción: UPDATE, DELETE y TRUNCATE rechazados (SQLSTATE 23001). [trigger historial_tag_sin_truncate: TRUNCATE] Solo inserción: UPDATE, DELETE y TRUNCATE rechazados (SQLSTATE 23001). [trigger historial_tag_solo_insercion: UPDATE DELETE] | H15: =COUNTIF(Columnas!$B:$B,B15) | I15: =COUNTIF(Relaciones!$A:$A,B15)
A16: Cadena de datos | B16: formula | C16: Librería de fórmulas del producto, versionada e igual para todos los clientes. Una fórmula produce UNA variable (tipo_tag) de una clase de equipo. Solo aparece en un tag que ES ese cálculo (fuente calculado). Hoy la única es f1-compresor-aire (PDT-1011). | E16: Producto (librería versionada, igual para todos los clientes). | F16: GET …/tags/:tag/procedencia → calculo | G16: Una sola versión activa por (clase de equipo, variable). Índice único: CREATE UNIQUE INDEX formula_una_activa ON "trim".formula USING btree (clase_equipo, tipo_tag) WHERE activa. | H16: =COUNTIF(Columnas!$B:$B,B16) | I16: =COUNTIF(Relaciones!$A:$A,B16)
A17: Cadena de datos | B17: calculo | C17: Qué fórmula (y qué versión) produce un tag calculado. Se llena al registrar un tag de fuente calculado con la fórmula activa de (clase del equipo, tipo del tag). Es procedencia.calculo. | E17: Servidor, al registrar un tag de fuente calculado. | F17: GET …/tags/:tag/procedencia → calculo | G17: Solo en tags de fuente calculado; hoy el único es PDT-1011. | H17: =COUNTIF(Columnas!$B:$B,B17) | I17: =COUNTIF(Relaciones!$A:$A,B17)
A18: Cadena de datos | B18: calculo_entrada | C18: Tags de los que se deriva un tag calculado (PDT-1011 ← PT-1011): su reloj es «el tag del que se deriva». | E18: Servidor (librería de fórmulas). | F18: GET …/tags/:tag/procedencia | H18: =COUNTIF(Columnas!$B:$B,B18) | I18: =COUNTIF(Relaciones!$A:$A,B18)
A19: Cadena de datos | B19: calibracion | C19: Calibración vigente de un tag de medición en custodia (solo donde de verdad existe: computador de flujo, analizador de BSW, medidores de tanque). La declara el DBIRTH (metricas[].calibracion); lo anterior pasa a historial_tag. Es custodia.calibracion de la procedencia. | D19: Dispositivo.calibracion (src/entities/tipos.ts); procedencia.custodia.calibracion | E19: Borde (metricas[].calibracion del DBIRTH). | F19: GET …/tags/:tag/procedencia → custodia | G19: Solo donde de verdad hay medición en custodia. Si el borde deja de declararla, se quita (y lo anterior queda en historial_tag). | H19: =COUNTIF(Columnas!$B:$B,B19) | I19: =COUNTIF(Relaciones!$A:$A,B19)
A20: Series | B20: lectura | C20: Serie de tiempo de cada tag: lo que llega del borde en DDATA (Sparkplug B) o del historiador. Particionada por mes. De aquí sale GET /api/campos/:campo/tags/:tag/serie (SerieTag, src/entities/tipos.ts: desde, pasoH, valores con null en los huecos) y la serie de cada dispositivo y señal en las vistas. Un hueco del historiador es la AUSENCIA de filas (o una fila de calidad mala): nunca un 0. | D20: SerieTag (src/entities/tipos.ts) | E20: Borde (DDATA de Sparkplug B) o el lector del historiador. | F20: GET /api/campos/:campo/tags/:tag/serie?desde&paso serie de cada dispositivo y señal en /api/vistas/… | G20: Un hueco es ausencia de filas o calidad mala: viaja como null EN SU LUGAR, nunca como 0. Particionada por mes (hora de Colombia); sin partición por defecto. | H20: =COUNTIF(Columnas!$B:$B,B20) | I20: =COUNTIF(Relaciones!$A:$A,B20)
A21: Insumos del motor | B21: pozo | C21: Pozo de un campo (Pozo, src/entities/pozos.ts). GET /api/campos/:campo/pozos y refs.pozos["campo/pozo"]. Sin origen y sin pruebas el pozo no tiene custodia: no se le asigna caudal. | D21: Pozo (src/entities/pozos.ts) | E21: Registro de ingeniería / maestro de pozos del cliente. | F21: GET /api/campos/:campo/pozos refs.pozos["campo/pozo"] GET /api/catalogo → campos[c].pozos | G21: Sin origen y sin pruebas no tiene custodia: no se le asigna caudal. | H21: =COUNTIF(Columnas!$B:$B,B21) | I21: =COUNTIF(Relaciones!$A:$A,B21)
A22: Insumos del motor | B22: prueba_pozo | C22: Prueba de pozo (Prueba, src/entities/pozos.ts; Pozo.pruebas). Rige desde su fecha hasta la siguiente; antes de la primera rige la primera (pruebaEn). Con el factor de asignación del mes da el crudo del pozo. | D22: Prueba (src/entities/pozos.ts) | E22: Borde (separador de prueba automatizado) o estimación de la propia electrosumergible. | F22: GET /api/campos/:campo/pozos → pruebas[] | G22: Rige desde su fecha hasta la siguiente; antes de la primera rige la primera (pruebaEn). | H22: =COUNTIF(Columnas!$B:$B,B22) | I22: =COUNTIF(Relaciones!$A:$A,B22)
A23: Insumos del motor | B23: evento | C23: Supertipo de los eventos del borde: un id único para todo el sistema (refs.eventos["id"] del contrato). clase pozo → evento_pozo, bomba → parada_bomba, servicio → evento_servicio. | D23: refs.eventos (clave común de EventoPozo y EventoBomba) | E23: Servidor, al registrar cualquier evento del borde. | F23: (interna: destino de las FK a «un evento») | G23: Un id es único en todo el sistema. Solo inserción. Único: (id, clase, campo_id, activo). Solo inserción: UPDATE, DELETE y TRUNCATE rechazados (SQLSTATE 23001). [trigger evento_sin_truncate: TRUNCATE] Solo inserción: UPDATE, DELETE y TRUNCATE rechazados (SQLSTATE 23001). [trigger evento_solo_insercion: UPDATE DELETE] | H23: =COUNTIF(Columnas!$B:$B,B23) | I23: =COUNTIF(Relaciones!$A:$A,B23)
A24: Insumos del motor | B24: evento_pozo | C24: Evento del controlador de un pozo (EventoPozo, src/entities/pozos.ts): variador, controlador de bombeo o válvula de cabeza. GET /api/campos/:campo/pozos/eventos y refs.eventos. Es la unidad de cobro del libro. Eventos que se pisan en el mismo pozo: se guardan como llegan y el motor los normaliza (intervalosEfectivos, libro.ts) — capítulo 4. | D24: EventoPozo (src/entities/pozos.ts) | E24: Borde (controlador del pozo: variador, controlador de bombeo, válvula de cabeza). | F24: GET /api/campos/:campo/pozos/eventos?desde&hasta refs.eventos | G24: La hora la pone el PLC y no se corrige: solo se cierra (fin) una vez. Eventos que se pisan: se guardan como llegan y el motor los normaliza (un paro manda sobre un HZ; entre iguales, el primero). Solo inserción: UPDATE, DELETE y TRUNCATE rechazados (SQLSTATE 23001). [trigger evento_pozo_sin_truncate: TRUNCATE] La hora del PLC no se corrige: solo se pone fin a un evento abierto (una vez) y, en una parada, la firma (una vez); no se borra. [trigger evento_pozo_solo_cierre: UPDATE DELETE] | H24: =COUNTIF(Columnas!$B:$B,B24) | I24: =COUNTIF(Relaciones!$A:$A,B24)
A25: Insumos del motor | B25: evento_servicio | C25: Caída de un servicio o equipo de proceso que apaga o frena pozos (EventoServicio, src/entities/pozos.ts). GET /api/campos/:campo/servicios/eventos. OJO: el tipo TS exige fin; la base admite NULL (servicio caído ahora) y el endpoint de insumo decide cómo entregarlo (capítulo 4, Huecos). | D25: EventoServicio (src/entities/pozos.ts) | E25: Borde (PLC o IED del servicio). | F25: GET /api/campos/:campo/servicios/eventos?desde&hasta | G25: fin NULL = sigue caído (el tipo TS todavía exige fin: ver Huecos). Solo inserción: UPDATE, DELETE y TRUNCATE rechazados (SQLSTATE 23001). [trigger evento_servicio_sin_truncate: TRUNCATE] La hora del PLC no se corrige: solo se pone fin a un evento abierto (una vez) y, en una parada, la firma (una vez); no se borra. [trigger evento_servicio_solo_cierre: UPDATE DELETE] | H25: =COUNTIF(Columnas!$B:$B,B25) | I25: =COUNTIF(Relaciones!$A:$A,B25)
A26: Insumos del motor | B26: parada_bomba | C26: Parada (o pérdida de caudal) de una bomba de la línea según su PLC (EventoBomba, src/entities/bombas.ts). GET /api/campos/:campo/bombas/:equipo/paradas. La parte NO viene escrita a mano: sale de la primera alarma o de la firma de las señales al parar. | D26: EventoBomba (src/entities/bombas.ts) | E26: Borde (PLC de la bomba); la firma, el servidor con las lecturas del instante de parar. | F26: GET /api/campos/:campo/bombas/:equipo/paradas?desde&hasta | G26: La parte nunca se escribe a mano: sale de la primera alarma o de la firma. La firma se pone una vez y no cambia al cerrarse la parada. Solo inserción: UPDATE, DELETE y TRUNCATE rechazados (SQLSTATE 23001). [trigger parada_bomba_sin_truncate: TRUNCATE] La hora del PLC no se corrige: solo se pone fin a un evento abierto (una vez) y, en una parada, la firma (una vez); no se borra. [trigger parada_bomba_solo_cierre: UPDATE DELETE] | H26: =COUNTIF(Columnas!$B:$B,B26) | I26: =COUNTIF(Relaciones!$A:$A,B26)
A27: Insumos del motor | B27: punto_medicion | C27: Punto de medición oficial de un campo (OrigenPmo de src/entities/insumos.ts, y Equipo.fiscal). GET /api/catalogo → medicion.origen y produccion-diaria.origen. Uno por campo: el motor lleva un fiscal por campo. | D27: OrigenPmo (src/entities/insumos.ts) y Equipo.fiscal | E27: Implementación (registro del punto de medición oficial). | F27: GET /api/campos/:campo/produccion-diaria → origen GET /api/catalogo → medicion.origen | G27: Uno por campo. | H27: =COUNTIF(Columnas!$B:$B,B27) | I27: =COUNTIF(Relaciones!$A:$A,B27)
A28: Insumos del motor | B28: mes_fiscal | C28: Estado fiscal de un mes de un campo (la parte publicado de ProduccionMes, src/entities/pozos.ts). Cada campo publica su mes por su cuenta. El calendario de GET /api/catalogo sale de aquí (publicado = todos los campos con fiscal lo publicaron). | D28: ProduccionMes.publicado (src/entities/pozos.ts); Mes (libro.ts) | E28: Servidor, cuando el campo publica su mes fiscal (contabilidad de hidrocarburos). | F28: GET /api/campos/:campo/produccion-diaria → meses[].publicado GET /api/catalogo → calendario | G28: Cada campo publica su mes por su cuenta. | H28: =COUNTIF(Columnas!$B:$B,B28) | I28: =COUNTIF(Relaciones!$A:$A,B28)
A29: Insumos del motor | B29: produccion_fiscal_diaria | C29: Barriles netos de cada día en el punto de medición oficial (ProduccionMes.dias). GET /api/campos/:campo/produccion-diaria arma por mes el arreglo dias[] con null donde no hay fila o bbl es NULL. Un día sin dato del computador de flujo NO es cero: no entra ni en lo real ni en el potencial y el libro no se publica. | D29: ProduccionMes.dias (src/entities/pozos.ts) | E29: Borde (computador de flujo del punto de medición oficial, ticket diario). | F29: GET /api/campos/:campo/produccion-diaria?desde&hasta | G29: NULL o día ausente = sin dato, nunca 0. El día de hoy es parcial (cerrado = false). | H29: =COUNTIF(Columnas!$B:$B,B29) | I29: =COUNTIF(Relaciones!$A:$A,B29)
A30: Insumos del motor | B30: metrologia_campo | C30: Registro de metrología de un campo, versionado (MetrologiaCampo, src/entities/metrologia.ts). GET /api/campos/:campo/metrologia y catalogo.medicion.metrologia toman la fila vigente. Con °API y la producción fiscal publicada se escoge la fila de la Fig. 10.2 (banda_regulatoria); un presupuesto demostrado (API MPMS 13.3 / ISO 5168) la reemplaza. | D30: MetrologiaCampo (src/entities/metrologia.ts) | E30: Laboratorio / metrología del cliente. | F30: GET /api/campos/:campo/metrologia GET /api/catalogo → medicion.metrologia | G30: °API NULL = banda no verificable: el libro no se publica (nunca 0 °API). | H30: =COUNTIF(Columnas!$B:$B,B30) | I30: =COUNTIF(Relaciones!$A:$A,B30)
... A35: Insumos del motor | B35: alarma_tag | C35: Base maestra de alarmas (ISA-18.2): el punto de alarma de cada tag con su norma u hoja de datos (Alarma de src/entities/bombas.ts, LimiteTag.alarma de limites.ts). Versionada y de solo inserción: rige la fila más nueva con vigente_desde ≤ t. Sin fila, el vigía responde «sin límite». | D35: Alarma (bombas.ts); LimiteTag.alarma (limites.ts) | E35: Ingeniería de confiabilidad del cliente (base maestra de alarmas, ISA-18.2). | F35: GET /api/catalogo → limites[tag].alarma | G35: Sin alarma, el vigía responde «sin límite». Solo inserción: un cambio es una fila nueva con su fecha. Solo inserción: UPDATE, DELETE y TRUNCATE rechazados (SQLSTATE 23001). [trigger alarma_tag_sin_truncate: TRUNCATE] Solo inserción: UPDATE, DELETE y TRUNCATE rechazados (SQLSTATE 23001). [trigger alarma_tag_solo_insercion: UPDATE DELETE] | H35: =COUNTIF(Columnas!$B:$B,B35) | I35: =COUNTIF(Relaciones!$A:$A,B35)
A36: Insumos del motor | B36: ajuste_variador | C36: Ajustes de protección del variador de cada electrosumergible (configuración del pozo): banda normal y alarma de sus cinco señales. Hoy NO tienen endpoint en el contrato: referencia/insumos/<campo>/electrosumergibles.json los trae con "endpoint": null (Pendiente del lado del servidor). | D36: Senal.normal y Senal.alarma de la electrosumergible (src/entities/esp.ts) | E36: Borde (lectura de los ajustes de protección del variador). | F36: (sin endpoint: referencia/insumos/<campo>/electrosumergibles.json, endpoint null) | H36: =COUNTIF(Columnas!$B:$B,B36) | I36: =COUNTIF(Relaciones!$A:$A,B36)
A37: Insumos del motor | B37: modo_falla | C37: Modos de falla de ISO 14224:2016, Anexo B (tablas B.6–B.15): MODOS de src/entities/iso14224.ts, con el nombre en palabras de campo (MODO_EN_CAMPO de catalogo.ts). Es «lo que se vio». | D37: Modo (src/entities/iso14224.ts) | E37: Producto (ISO 14224). | F37: GET /api/catalogo → catalogosDanos GET /api/vistas/paradas/:evento/opciones | H37: =COUNTIF(Columnas!$B:$B,B37) | I37: =COUNTIF(Relaciones!$A:$A,B37)
A38: Insumos del motor | B38: mecanismo_falla | C38: Mecanismos de falla de ISO 14224:2016 Table B.2 (MECANISMOS de src/entities/iso14224.ts). Transcrita, pendiente de cotejo con la norma comprada. Solo lo de degradación se proyecta con una tendencia. | D38: Mecanismo (src/entities/iso14224.ts) | E38: Producto (ISO 14224 Table B.2, pendiente de cotejo). | F38: POST /api/analisis/:evento (valida) | G38: Solo lo de degradación se proyecta con una tendencia. | H38: =COUNTIF(Columnas!$B:$B,B38) | I38: =COUNTIF(Relaciones!$A:$A,B38)
A39: Insumos del motor | B39: causa_raiz | C39: Las cinco categorías de causa raíz de primer nivel de ISO 14224 Table B.3 (CAUSAS_RAIZ de src/entities/iso14224.ts). | D39: CAUSAS_RAIZ (src/entities/iso14224.ts) | E39: Producto (ISO 14224 Table B.3). | F39: POST /api/analisis/:evento (valida) | H39: =COUNTIF(Columnas!$B:$B,B39) | I39: =COUNTIF(Relaciones!$A:$A,B39)
A40: Insumos del motor | B40: modo_por_clase | C40: Qué modos aplican a cada clase de equipo (ISO 14224 B.2.6; MODOS_POR_CLASE de src/entities/iso14224.ts). | D40: MODOS_POR_CLASE (src/entities/iso14224.ts) | E40: Producto. | F40: GET /api/catalogo → catalogosDanos | G40: Único: (clase_iso, orden). | H40: =COUNTIF(Columnas!$B:$B,B40) | I40: =COUNTIF(Relaciones!$A:$A,B40)
A41: Insumos del motor | B41: clase_catalogo | C41: Clases del catálogo de daños (ClaseCatalogo y NOMBRE_CLASE_EQUIPO de src/entities/catalogo.ts) y la familia de partes de cada una. | D41: ClaseCatalogo, Catalogo.clase (src/entities/catalogo.ts) | E41: Producto. | F41: GET /api/catalogo → catalogosDanos[equipo].clase | G41: Único: (familia). | H41: =COUNTIF(Columnas!$B:$B,B41) | I41: =COUNTIF(Relaciones!$A:$A,B41)
A42: Insumos del motor | B42: clase_iso_catalogo | C42: De la clase ISO del registro y el papel de la bomba al catálogo de daños (claseDeCatalogo de src/entities/catalogo.ts). Se busca primero el papel exacto y si no, *. Una clase sin fila no tiene catálogo de partes. | D42: claseDeCatalogo (src/entities/catalogo.ts) | E42: Producto. | F42: GET /api/catalogo → catalogosDanos | G42: Se busca el papel exacto y si no, *. | H42: =COUNTIF(Columnas!$B:$B,B42) | I42: =COUNTIF(Relaciones!$A:$A,B42)
A43: Insumos del motor | B43: parte | C43: Partes (ítem mantenible, nivel 8 de ISO 14224) de cada familia (Parte de src/entities/partes.ts; PARTES_INYECCION, PARTES_MULTIFASICA, PARTES_ESP). Librería del producto, versionada con el código. | D43: Parte (src/entities/partes.ts) | E43: Producto. | F43: GET /api/catalogo → catalogosDanos[equipo].partes | G43: Único: (familia, orden). | H43: =COUNTIF(Columnas!$B:$B,B43) | I43: =COUNTIF(Relaciones!$A:$A,B43)
A44: Insumos del motor | B44: parte_variable | C44: Variables de la familia que dicen algo de la parte, con su papel: avisa (anticipa), causa (la daña) o confirma (cambia cuando ya empezó). Parte.variables de partes.ts. | D44: Parte.variables (src/entities/partes.ts) | E44: Producto. | F44: GET /api/catalogo → catalogosDanos | H44: =COUNTIF(Columnas!$B:$B,B44) | I44: =COUNTIF(Relaciones!$A:$A,B44)
...

Sheet Columnas
A1: Grupo | B1: Tabla | C1: Columna | D1: Tipo | E1: Nulo | F1: PK | G1: FK (tabla.columna) | H1: Único | I1: CHECK | J1: Descripción | K1: Ejemplo
A2: Registro de campos y planta | B2: campo | C2: id | D2: text | E2: no | F2: sí | I2: CHECK (((btrim(id) <> ''::text) AND (id = btrim(id)))) | J2: Id del campo: único, no vacío y sin espacios en los bordes (ceiba, morichal…). Es la clave que usan todas las demás tablas. | K2: ceiba
A3: Registro de campos y planta | B3: campo | C3: nombre | D3: text | E3: no | I3: CHECK ((btrim(nombre) <> ''::text)) | J3: Nombre para leer (La Ceiba). | K3: La Ceiba
A4: Registro de campos y planta | B4: campo | C4: cuenca | D4: text | E4: no | J4: Cuenca sedimentaria (Magdalena Medio, Llanos, Putumayo…). | K4: Llanos
A5: Registro de campos y planta | B5: campo | C5: choke | D5: text | E5: no | I5: CHECK ((choke = ANY (ARRAY['Pozos'::text, 'Planta'::text, 'Evacuación'::text, 'Mercado'::text]))) | J5: Qué limita al campo, dicho por la operación: Pozos, Planta, Evacuación o Mercado. Descriptivo. | K5: Planta
A6: Registro de campos y planta | B6: campo | C6: nota | D6: text | E6: no | J6: Nota libre del registro. | K6: Tres bombas de agua en paralelo, sin reserva: si para una, se cierran pozos.
A7: Registro de campos y planta | B7: activo | C7: campo_id | D7: text | E7: no | F7: sí | G7: campo.id | H7: único con (campo_id, codigo, clase) | J7: Campo del activo. | K7: ceiba
A8: Registro de campos y planta | B8: activo | C8: codigo | D8: text | E8: no | F8: sí | H8: único con (campo_id, codigo, clase) | I8: CHECK ((btrim(codigo) <> ''::text)) | J8: Código del activo en el campo (P-201B, K-101, LC-14). | K8: C-401
A9: Registro de campos y planta | B9: activo | C9: clase | D9: text | E9: no | H9: único con (campo_id, codigo, clase) | I9: CHECK ((clase = ANY (ARRAY['catalogo'::text, 'pozo'::text]))) | J9: catalogo (equipo de superficie del registro de ingeniería) o pozo. | K9: catalogo
A10: Registro de campos y planta | B10: equipo | C10: campo_id | D10: text | E10: no | F10: sí | G10: activo.campo_id | J10: Campo. | K10: ceiba
A11: Registro de campos y planta | B11: equipo | C11: codigo | D11: text | E11: no | F11: sí | G11: activo.codigo | J11: Código del equipo (P-201B). | K11: C-401
A12: Registro de campos y planta | B12: equipo | C12: clase | D12: text | E12: no | G12: activo.clase | I12: CHECK ((clase = 'catalogo'::text)) | J12: Siempre catalogo: amarra la fila al supertipo activo. | K12: catalogo
A13: Registro de campos y planta | B13: equipo | C13: nombre | D13: text | E13: no | I13: CHECK ((btrim(nombre) <> ''::text)) | J13: Nombre del equipo. | K13: Compresor de gas
A14: Registro de campos y planta | B14: equipo | C14: sistema | D14: text | E14: no | J14: Sistema al que pertenece (Tratamiento de agua, Servicios industriales…). | K14: Compresión
A15: Registro de campos y planta | B15: equipo | C15: clase_iso | D15: text | E15: no | I15: CHECK ((btrim(clase_iso) <> ''::text)) | J15: Clase de equipo de la taxonomía ISO 14224 (bomba-centrifuga, compresor-aire, unidad-lact…). De ella y del papel de la bomba sale el catálogo de daños (clase_iso_catalogo). | K15: compresor-gas
A16: Registro de campos y planta | B16: equipo | C16: criticidad | D16: smallint | E16: no | I16: CHECK (((criticidad >= 1) AND (criticidad <= 5))) | J16: Criticidad 1 a 5 del registro del cliente. | K16: 4
A17: Registro de campos y planta | B17: equipo | C17: servicio | D17: text | E17: sí | I17: CHECK ((servicio = ANY (ARRAY['aire'::text, 'energia'::text, 'compresion'::text, 'evacuacion'::text, 'proceso'::text, 'tratamiento'::text]))) | J17: Si al caer apaga pozos: el tipo de causa que se le carga (aire, energia, compresion, evacuacion, proceso, tratamiento). NULL si no es un servicio. | K17: compresion
A18: Registro de campos y planta | B18: equipo | C18: modo_falla | D18: text | E18: sí | J18: Modo de falla dominante de la familia, para leer. | K18: Válvulas de succión y descarga ≈ 50,7 %
A19: Registro de campos y planta | B19: equipo | C19: norma | D19: text | E19: sí | J19: Norma o referencia técnica que rige la vigilancia del equipo. | K19: El modo de falla #1 de la familia NO es monitoreable a nuestra resolución: se diagnostica por ángulo de cigüeñal.
A20: Registro de campos y planta | B20: equipo | C20: intervencion_ubicacion | D20: text | E20: sí | I20: CHECK ((((intervencion_ubicacion IS NULL) = (intervencion_accion IS NULL)) AND ((intervencion_accion IS NULL) = (intervencion_avisar_a IS NULL)))) | J20: Dónde está, para ir al equipo (Equipo.intervencion.ubicacion). Es de ESTE campo. | K20: Batería 1 · tren de gas
A21: Registro de campos y planta | B21: equipo | C21: intervencion_accion | D21: text | E21: sí | I21: CHECK ((((intervencion_ubicacion IS NULL) = (intervencion_accion IS NULL)) AND ((intervencion_accion IS NULL) = (intervencion_avisar_a IS NULL)))) | J21: Acción inmediata (Equipo.intervencion.accionInmediata). | K21: Ante parada súbita, verificar presión de descarga y temperatura por etapa antes de reponer: el modo dominante no avisa.
A22: Registro de campos y planta | B22: equipo | C22: intervencion_avisar_a | D22: text | E22: sí | I22: CHECK ((((intervencion_ubicacion IS NULL) = (intervencion_accion IS NULL)) AND ((intervencion_accion IS NULL) = (intervencion_avisar_a IS NULL)))) | J22: A quién avisar (Equipo.intervencion.avisarA). | K22: Supervisor de operaciones
A23: Registro de campos y planta | B23: equipo | C23: distribucion_falla | D23: jsonb | E23: sí | J23: Reparto de modos de falla de la familia con su fuente bibliográfica: {"reparto":[["Mecánicas",44.1],…],"fuente":"…"} (Equipo.distribucionFalla). | K23: {'fuente': '21 compresores de pistón a lo largo de 20 años. Succión y descarga suman 50,7 %: es el modo de falla #1 de la familia.', 'reparto': [['Válvulas de succión', 29.1], ['Válvulas de descarga', 21.6], ['Resto de elementos', 49.3]]}
A24: Registro de campos y planta | B24: equipo | C24: aguas_abajo | D24: text | E24: sí | I24: CHECK ((btrim(aguas_abajo) <> ''::text)) | J24: Lo que queda sin servicio si el equipo para, como lo declara el registro del campo (Equipo.aguasAbajo: «todo el campo», «4 pozos», «tren de gas», «sin impacto»). El motor lo compara: un servicio en alarma con «todo el campo» entra en el riesgo de ahora. NULL en las bombas de la línea: ahí lo dice el respaldo firmado (respaldoEnCampo de equipos.ts), y en una bomba sin perfil en el campo la API dice «sin declarar en este campo». | K24: tren de gas
A25: Registro de campos y planta | B25: equipo | C25: redundancia | D25: text | E25: sí | I25: CHECK ((btrim(redundancia) <> ''::text)) | J25: Respaldo del equipo en el campo, para leer (Equipo.redundancia: «3 unidades (N+1)», «respaldo en línea (H-301)», «sin respaldo»). NULL en las bombas de la línea: lo dice el respaldo firmado (respaldo.detalle, o «sin respaldo» con libre_bpd = 0). | K25: sin respaldo
A26: Registro de campos y planta | B26: planta_campo | C26: campo_id | D26: text | E26: no | F26: sí | G26: campo.id | J26: Campo. | K26: ceiba
A27: Registro de campos y planta | B27: planta_campo | C27: crudo_bpd | D27: numeric | E27: no | I27: CHECK ((crudo_bpd >= (0)::numeric)) | J27: Caudales.crudo: crudo que mueve la planta, bbl/d. | K27: 10450
A28: Registro de campos y planta | B28: planta_campo | C28: crudo_cap_bpd | D28: numeric | E28: no | I28: CHECK ((crudo_cap_bpd >= (0)::numeric)) | J28: Caudales.crudoCap: capacidad del tren de crudo, bbl/d. | K28: 12000
A29: Registro de campos y planta | B29: planta_campo | C29: agua_bpd | D29: numeric | E29: no | I29: CHECK ((agua_bpd >= (0)::numeric)) | J29: Caudales.agua: agua producida, bbl/d. | K29: 224200
A30: Registro de campos y planta | B30: planta_campo | C30: agua_cap_bpd | D30: numeric | E30: no | I30: CHECK ((agua_cap_bpd >= (0)::numeric)) | J30: Caudales.aguaCap: capacidad del tren de agua, bbl/d. | K30: 267750
A31: Registro de campos y planta | B31: planta_campo | C31: gas_bpd | D31: numeric | E31: no | I31: CHECK ((gas_bpd >= (0)::numeric)) | J31: Caudales.gas, en la unidad del tren de gas. | K31: 3850
A32: Registro de campos y planta | B32: planta_campo | C32: gas_cap_bpd | D32: numeric | E32: no | I32: CHECK ((gas_cap_bpd >= (0)::numeric)) | J32: Caudales.gasCap. 0 = el campo no tiene tren de gas. | K32: 4200
A33: Registro de campos y planta | B33: planta_campo | C33: choke_pozos | D33: numeric | E33: no | J33: Chokes.pozos (modelo NSTA/SPE). | K33: 12500
A34: Registro de campos y planta | B34: planta_campo | C34: choke_planta | D34: numeric | E34: no | J34: Chokes.planta. | K34: 11800
A35: Registro de campos y planta | B35: planta_campo | C35: choke_evacuacion | D35: numeric | E35: no | J35: Chokes.evacuacion. | K35: 14000
A36: Registro de campos y planta | B36: planta_campo | C36: choke_mercado | D36: numeric | E36: no | J36: Chokes.mercado. | K36: 15000
A37: Registro de campos y planta | B37: planta_campo | C37: nota | D37: text | E37: no | J37: PlantaCampo.nota. | K37: El agua (95 % de lo que sale de los pozos) la sacan tres bombas en paralelo, P-201A, B y C, de 90.000 bbl/d de placa; el cabezal de disposición las limita a unos 89.250 cada una. Si para una, las otras dos no alcanzan: el tanque se llena en un par de horas y hay que cerrar parte de los pozos. Es el cuello de botella del campo.
A38: Registro de campos y planta | B38: planta_elemento | C38: campo_id | D38: text | E38: no | F38: sí | G38: activo.campo_id · planta_campo.campo_id | H38: único con (campo_id, tren, orden) | J38: Campo. | K38: ceiba
A39: Registro de campos y planta | B39: planta_elemento | C39: id | D39: text | E39: no | F39: sí | I39: CHECK ((btrim(id) <> ''::text)) | J39: Id del elemento. Un id identifica una sola cosa en el campo: no se repite entre elementos ni miembros (trigger planta_id_unico). | K39: aire
A40: Registro de campos y planta | B40: planta_elemento | C40: tren | D40: text | E40: no | H40: único con (campo_id, tren, orden) | I40: CHECK ((tren = ANY (ARRAY['tronco'::text, 'gas'::text, 'crudo'::text, 'agua'::text, 'servicios'::text]))) | J40: Tren: tronco, gas, crudo, agua o servicios. | K40: servicios
...

Sheet Relaciones
A1: Tabla | B1: Columna | C1: Apunta a la tabla | D1: Columna | E1: Cardinalidad | F1: Qué significa
A2: activo | B2: campo_id | C2: campo | D2: id | E2: N:1 | F2: Campo del activo.
A3: equipo | B3: campo_id, codigo, clase | C3: activo | D3: campo_id, codigo, clase | E3: 1:1 | F3: Campo.
A4: planta_campo | B4: campo_id | C4: campo | D4: id | E4: 1:1 | F4: Campo.
A5: planta_elemento | B5: campo_id, equipo | C5: activo | D5: campo_id, codigo | E5: N:1 | F5: Campo.
A6: planta_elemento | B6: campo_id | C6: planta_campo | D6: campo_id | E6: N:1 | F6: Campo.
A7: planta_miembro | B7: campo_id, elemento_id | C7: planta_elemento | D7: campo_id, id | E7: N:1 | F7: Campo.
A8: planta_miembro | B8: campo_id, equipo | C8: activo | D8: campo_id, codigo | E8: N:1 | F8: Campo.
A9: gateway | B9: campo_id | C9: campo | D9: id | E9: N:1 | F9: Campo donde se inscribió. Los tags que publica son de este campo (FK compuesta en fuente/dispositivo/tag).
A10: inscripcion | B10: campo_id | C10: campo | D10: id | E10: N:1 | F10: Campo para el que se emitió: el gateway que lo canjea queda de este campo.
A11: inscripcion | B11: emitido_por | C11: usuario | D11: id | E11: N:1 | F11: Id de la persona que lo pidió (del token; capacidad conector:configurar).
A12: inscripcion | B12: gateway_id | C12: gateway | D12: id | E12: N:1 | F12: Gateway que lo canjeó.
... A145: recalculo_mes | B145: campo_id | C145: campo | D145: id | E145: N:1 | F145: Campo.

Sheet Filas de ejemplo
A1: campo
A2: id | B2: nombre | C2: cuenca | D2: choke | E2: nota
A3: ceiba | B3: La Ceiba | C3: Llanos | D3: Planta | E3: Tres bombas de agua en paralelo, sin reserva: si para una, se cierran pozos.
A4: guacamayo | B4: Guacamayo | C4: Putumayo | D4: Evacuación | E4: La reinyección es para recobro: el agua tiene salida alterna.
A5: morichal | B5: Morichal Norte | C5: Llanos | D5: Pozos | E5: Todos sus pozos con electrosumergible; la reinyección tiene respaldo parcial.
A6: palmar | B6: El Palmar | C6: Magdalena Medio | D6: Planta | E6: Campo chico de bombeo mecánico.
A7: zarza | B7: La Zarza | C7: Llanos | D7: Mercado | E7: Gas con condensado: lo limita la nominación del comprador.
A9: activo
A10: campo_id | B10: codigo | C10: clase
A11: ceiba | B11: C-401 | C11: catalogo
A12: ceiba | B12: H-302 | C12: catalogo
A13: ceiba | B13: K-101 | C13: catalogo
A14: ceiba | B14: LACT-01 | C14: catalogo
A15: ceiba | B15: P-201B | C15: catalogo
A17: equipo
A18: campo_id | B18: codigo | C18: clase | D18: nombre | E18: sistema | F18: clase_iso | G18: criticidad | H18: servicio | I18: modo_falla | J18: norma | K18: intervencion_ubicacion | L18: intervencion_accion | M18: intervencion_avisar_a | N18: distribucion_falla | O18: aguas_abajo | P18: redundancia
A19: ceiba | B19: C-401 | C19: catalogo | D19: Compresor de gas | E19: Compresión | F19: compresor-gas | G19: 4 | H19: compresion | I19: Válvulas de succión y descarga ≈ 50,7 % | J19: El modo de falla #1 de la familia NO es monitoreable a nuestra resolución: se diagnostica por ángulo de cigüeñal. | K19: Batería 1 · tren de gas | L19: Ante parada súbita, verificar presión de descarga y temperatura por etapa antes de reponer: el modo dominante no avisa. | M19: Supervisor de operaciones | N19: {"fuente": "21 compresores de pistón a lo largo de 20 años. Succión y descarga suman 50,7 %: es el modo de falla #1 de la familia.", "reparto": [["Válvulas de succión", 29.1], ["Válvulas de descarga", 21.6], ["Resto de elementos", 49.3]]} | O19: tren de gas | P19: sin respaldo
A20: ceiba | B20: H-302 | C20: catalogo | D20: Tratador térmico | E20: Tratamiento de crudo | F20: tratador-termico | G20: 4 | H20: tratamiento | I20: Escama y impingimiento de llama | J20: Variable: temperatura de piel de tubo. Intervalo P-F: varía ampliamente. | K20: Batería 1 · tren de crudo | L20: No requiere intervención inmediata: H-301 toma la carga. Programar la limpieza del tubo de fuego en la próxima ventana. | M20: Planeación de mantenimiento | O20: sin impacto | P20: respaldo en línea (H-301)
A21: ceiba | B21: K-101 | C21: catalogo | D21: Sistema de aire de instrumentos | E21: Servicios industriales | F21: compresor-aire | G21: 5 | H21: aire | I21: Pérdida de suministro → válvulas a posición segura | J21: ISA-7.0.01 · API RP 14J §3.3.16. «El diseño a prueba de fallo no elimina la necesidad de supervivencia de la utilidad.» | K21: Batería 1 · servicios industriales | L21: Verificar que las tres unidades estén en servicio: hoy hay dos. Con el recibidor en 11 min de autonomía, una parada deja las válvulas en posición segura. | M21: Supervisor de operaciones | O21: todo el campo | P21: 3 unidades (N+1)
A22: ceiba | B22: LACT-01 | C22: catalogo | D22: Unidad LACT · punto de medición oficial | E22: Medición fiscal | F22: unidad-lact | G22: 5 | H22: evacuacion | I22: Deriva del factor de medidor | J22: El archivo EFM (horarios, diarios, eventos) exige ROC Plus o Totalflow, no Modbus plano. | O22: todo el campo | P22: sin respaldo
A23: ceiba | B23: P-201B | C23: catalogo | D23: Bomba multietapa de transferencia de agua | E23: Tratamiento de agua | F23: bomba-centrifuga | G23: 5 | I23: Lubricación de cojinete | J23: Centrífuga multietapa · API 610, Tabla 8: vibración en la caja de rodamientos. | K23: Batería 1 · tren de agua | L23: Llevar P-201A y P-201C a su caudal máximo y confirmar el nivel del tanque de agua antes de intentar el arranque: si ya está alto, cerrar primero los pozos con menos crudo por barril de agua. | M23: Supervisor de operaciones e ingeniería de producción | N23: {"fuente": "Reparto de bombeo en campo Sirte (Libia), 673 elementos de falla clasificados.", "reparto": [["Mecánicas", 44.1], ["Eléctricas", 27.7], ["Operacionales y de sistema", 25.4], ["Diseño", 2.4]]}
A25: planta_campo
A26: campo_id | B26: crudo_bpd | C26: crudo_cap_bpd | D26: agua_bpd | E26: agua_cap_bpd | F26: gas_bpd | G26: gas_cap_bpd | H26: choke_pozos | I26: choke_planta | J26: choke_evacuacion | K26: choke_mercado | L26: nota
A27: ceiba | B27: 10450 | C27: 12000 | D27: 224200 | E27: 267750 | F27: 3850 | G27: 4200 | H27: 12500 | I27: 11800 | J27: 14000 | K27: 15000 | L27: El agua (95 % de lo que sale de los pozos) la sacan tres bombas en paralelo, P-201A, B y C, de 90.000 bbl/d de placa; el cabezal de disposición las limita a unos 89.250 cada una. Si para una, las otras dos no alcanzan: el tanque se llena en un par de horas y hay que cerrar parte de los pozos. Es el cuello de botella del campo.
A28: guacamayo | B28: 6200 | C28: 7400 | D28: 90300 | E28: 110000 | F28: 2100 | G28: 2600 | H28: 7200 | I28: 7400 | J28: 6800 | K28: 9000 | L28: Sin compresión: el gas va a consumo propio y el excedente a tea. La restricción está aguas abajo del LACT, en la nominación del oleoducto.
A29: morichal | B29: 14800 | C29: 19500 | D29: 580400 | E29: 605500 | F29: 9100 | G29: 11000 | H29: 17950 | I29: 19500 | J29: 21000 | K29: 24000 | L29: Manda el levantamiento: 41 pozos con bomba electrosumergible y 97 % de agua, que sacan siete bombas casi al tope de lo que deja el cabezal de disposición. El compresor de gas, sin respaldo, ya cerró pozos cuando paró.
A30: palmar | B30: 3100 | C30: 3600 | D30: 13180 | E30: 16000 | F30: 0 | G30: 0 | H30: 3500 | I30: 3295 | J30: 4200 | K30: 5000 | L30: Campo chico de bombeo mecánico, sin tren de gas, con holgura en crudo y agua (80 % de agua, que saca una sola bomba de 16.000 bbl/d).
A31: zarza | B31: 2900 | C31: 3400 | D31: 1450 | E31: 4000 | F31: 12400 | G31: 16800 | H31: 3900 | I31: 3400 | J31: 4100 | K31: 3372 | L31: Campo de gas: el producto principal sale por arriba. Su restricción típica es comercial (la nominación del comprador), no técnica.
A33: planta_elemento
A34: campo_id | B34: id | C34: tren | D34: orden | E34: simbolo | F34: etiqueta | G34: equipo | H34: pie | I34: nivel_tag | J34: nivel_tope | K34: fluido | L34: pmo | M34: rama | N34: restantes_cuantos | O34: restantes_etiqueta
A35: ceiba | B35: aire | C35: servicios | D35: 1 | E35: aire | F35: Aire de instrumentos | G35: K-101 | M35: FALSE
A36: ceiba | B36: bomba | C36: agua | D36: 1 | E36: bomba | F36: Bombas de agua | G36: P-201B | M36: FALSE
A37: ceiba | B37: compresor | C37: gas | D37: 2 | E37: compresor | F37: Compresor de gas | G37: C-401 | M37: FALSE
A38: ceiba | B38: depurador | C38: gas | D38: 0 | E38: depurador | F38: Depurador de gas | H38: proceso | M38: FALSE
A39: ceiba | B39: gasventa | C39: gas | D39: 3 | E39: salida | F39: Gas a venta | H39: límite de batería | M39: FALSE
A41: planta_miembro
A42: campo_id | B42: elemento_id | C42: id | D42: orden | E42: etiqueta | F42: equipo | G42: pie | H42: nivel_tag | I42: nivel_tope | J42: fluido | K42: pmo
A43: ceiba | B43: pozos | C43: LC-09 | D43: 1 | E43: LC-09 · ESP | F43: LC-09
A44: ceiba | B44: pozos | C44: LC-14 | D44: 0 | E44: LC-14 · ESP | F44: LC-14
A45: ceiba | B45: pozos | C45: LC-21 | D45: 2 | E45: LC-21 · bombeo mecánico | F45: LC-21
...

Sheet Diagrama
